<?xml version="1.0" ?>
<robot name="bsl_plotter2" xmlns:xacro="http://www.ros.org/wiki/xacro">

<xacro:include filename="$(find bsl_plotter2_description)/urdf/materials.xacro" />
<xacro:include filename="$(find bsl_plotter2_description)/urdf/bsl_plotter2.trans" />
<xacro:include filename="$(find bsl_plotter2_description)/urdf/bsl_plotter2.gazebo" />
<link name="base_link">
  <inertial>
    <origin xyz="0.02576751407527586 0.025767514075266288 0.0015162951999769865" rpy="0 0 0"/>
    <mass value="0.42665443770507006"/>
    <inertia ixx="0.000652" iyy="0.000652" izz="0.001299" ixy="0.000137" iyz="8e-06" ixz="8e-06"/>
  </inertial>
  <visual>
    <origin xyz="0 0 0" rpy="0 0 0"/>
    <geometry>
      <mesh filename="package://bsl_plotter2_description/meshes/base_link.stl" scale="0.001 0.001 0.001"/>
    </geometry>
    <material name="_"/>
  </visual>
  <collision>
    <origin xyz="0 0 0" rpy="0 0 0"/>
    <geometry>
      <mesh filename="package://bsl_plotter2_description/meshes/base_link.stl" scale="0.001 0.001 0.001"/>
    </geometry>
  </collision>
</link>

<link name="link_upper_arm_v5_1">
  <inertial>
    <origin xyz="0.10001075216740007 4.552712739598546e-06 0.018662529334321422" rpy="0 0 0"/>
    <mass value="0.7822732650505565"/>
    <inertia ixx="0.000187" iyy="0.004844" izz="0.004811" ixy="0.0" iyz="0.0" ixz="-0.000445"/>
  </inertial>
  <visual>
    <origin xyz="-0.0 -0.0 -0.012628" rpy="0 0 0"/>
    <geometry>
      <mesh filename="package://bsl_plotter2_description/meshes/link_upper_arm_v5_1.stl" scale="0.001 0.001 0.001"/>
    </geometry>
    <material name="_"/>
  </visual>
  <collision>
    <origin xyz="-0.0 -0.0 -0.012628" rpy="0 0 0"/>
    <geometry>
      <mesh filename="package://bsl_plotter2_description/meshes/link_upper_arm_v5_1.stl" scale="0.001 0.001 0.001"/>
    </geometry>
  </collision>
</link>

<link name="link_fore_arm_v3_1">
  <inertial>
    <origin xyz="0.09531883330237101 6.762503391622247e-05 0.01402398684768523" rpy="0 0 0"/>
    <mass value="0.6037538171570082"/>
    <inertia ixx="8e-05" iyy="0.001714" izz="0.001738" ixy="-2e-06" iyz="-0.0" ixz="-4.2e-05"/>
  </inertial>
  <visual>
    <origin xyz="-0.200015 -0.0 -0.049828" rpy="0 0 0"/>
    <geometry>
      <mesh filename="package://bsl_plotter2_description/meshes/link_fore_arm_v3_1.stl" scale="0.001 0.001 0.001"/>
    </geometry>
    <material name="_"/>
  </visual>
  <collision>
    <origin xyz="-0.200015 -0.0 -0.049828" rpy="0 0 0"/>
    <geometry>
      <mesh filename="package://bsl_plotter2_description/meshes/link_fore_arm_v3_1.stl" scale="0.001 0.001 0.001"/>
    </geometry>
  </collision>
</link>

<link name="link_hand_v4_1">
  <inertial>
    <origin xyz="0.010404677428966724 0.019249999999999205 -1.0531610050712459e-07" rpy="0 0 0"/>
    <mass value="0.036970130267254944"/>
    <inertia ixx="1.2e-05" iyy="4e-06" izz="1.2e-05" ixy="0.0" iyz="0.0" ixz="0.0"/>
  </inertial>
  <visual>
    <origin xyz="-0.350115 0.0186 -0.064546" rpy="0 0 0"/>
    <geometry>
      <mesh filename="package://bsl_plotter2_description/meshes/link_hand_v4_1.stl" scale="0.001 0.001 0.001"/>
    </geometry>
    <material name="_"/>
  </visual>
  <collision>
    <origin xyz="-0.350115 0.0186 -0.064546" rpy="0 0 0"/>
    <geometry>
      <mesh filename="package://bsl_plotter2_description/meshes/link_hand_v4_1.stl" scale="0.001 0.001 0.001"/>
    </geometry>
  </collision>
</link>

<joint name="rev1" type="continuous">
  <origin xyz="0.0 0.0 0.012628" rpy="0 0 0"/>
  <parent link="base_link"/>
  <child link="link_upper_arm_v5_1"/>
  <axis xyz="0.0 0.0 -1.0"/>
</joint>

<joint name="rev2" type="continuous">
  <origin xyz="0.200015 0.0 0.0372" rpy="0 0 0"/>
  <parent link="link_upper_arm_v5_1"/>
  <child link="link_fore_arm_v3_1"/>
  <axis xyz="0.0 -0.0 1.0"/>
</joint>

<joint name="rev3" type="continuous">
  <origin xyz="0.1501 -0.0186 0.014718" rpy="0 0 0"/>
  <parent link="link_fore_arm_v3_1"/>
  <child link="link_hand_v4_1"/>
  <axis xyz="0.0 -1.0 -0.0"/>
</joint>

</robot>
